Workbook

Sheet Leia-me
A1: Resultados do hands-on: Polling, Interrupcoes, Threads e Work Queue no Zephyr RTOS
A2: Leonardo Moreno - NUSP 13654481
A4: ORIGEM DOS DADOS
A5: Firmware real compilado com west build (Zephyr 4.5.0-rc2, Zephyr SDK 1.0.1, placa esp32_devkitc/esp32/procpu).
A6: Execucao EMULADA: QEMU da Espressif (esp-develop) com modelo de GPIO estendido (saida/entrada, interrupcao por borda, jumper GPIO18->GPIO4).
A7: Tempo virtual deterministico: -icount shift=2 (4 ns por instrucao, ~1 ciclo por instrucao a 240 MHz). Nao e medicao em placa fisica.
A8: Memoria (Flash/RAM) vem do build real e e identica a de uma placa com a mesma versao.
A10: ABAS
A11: Dados_LAT, Dados_SUM, Dados_Threads, Dados_Memoria, Dados_Manual: linhas extraidas dos logs brutos (pasta logs/).
A12: Exp1-3, Exp4, Exp5, Exp6, Exp7, Exp8: tabelas da apostila calculadas por formula a partir das abas de dados.
A13: Latencias em microssegundos (us); CPU e perdas em %. 'sem amostras' = nenhum evento detectado.

Sheet Dados_LAT
A1: experimento | B1: execucao | C1: modo | D1: metrica | E1: n | F1: min (ns) | G1: media (ns) | H1: max (ns) | I1: min (us) | J1: media (us) | K1: max (us)
A2: exp4_irq_thread_cpi2 | B2: 1 | C2: irq_thread | D2: lat_detect | E2: 200 | F2: 2204 | G2: 2204 | H2: 2208 | I2: =F2/1000 -> 2.204 | J2: =G2/1000 -> 2.204 | K2: =H2/1000 -> 2.208
A3: exp4_irq_thread_cpi2 | B3: 1 | C3: irq_thread | D3: lat_handoff | E3: 200 | F3: 6637 | G3: 6637 | H3: 6658 | I3: =F3/1000 -> 6.637 | J3: =G3/1000 -> 6.637 | K3: =H3/1000 -> 6.658
A4: exp4_irq_thread_cpi2 | B4: 1 | C4: irq_thread | D4: lat_process | E4: 200 | F4: 8845 | G4: 8845 | H4: 8866 | I4: =F4/1000 -> 8.845 | J4: =G4/1000 -> 8.845 | K4: =H4/1000 -> 8.866
A5: exp4_irq_thread_cpi2 | B5: 1 | C5: irq_thread | D5: lat_proc_dur | E5: 200 | F5: 358 | G5: 358 | H5: 362 | I5: =F5/1000 -> 0.358 | J5: =G5/1000 -> 0.358 | K5: =H5/1000 -> 0.362
A6: exp4_irq_thread | B6: 1 | C6: irq_thread | D6: lat_detect | E6: 200 | F6: 1104 | G6: 1104 | H6: 1104 | I6: =F6/1000 -> 1.104 | J6: =G6/1000 -> 1.104 | K6: =H6/1000 -> 1.104
A7: exp4_irq_thread | B7: 1 | C7: irq_thread | D7: lat_handoff | E7: 200 | F7: 3316 | G7: 3316 | H7: 3329 | I7: =F7/1000 -> 3.316 | J7: =G7/1000 -> 3.316 | K7: =H7/1000 -> 3.329
A8: exp4_irq_thread | B8: 1 | C8: irq_thread | D8: lat_process | E8: 200 | F8: 4420 | G8: 4420 | H8: 4433 | I8: =F8/1000 -> 4.42 | J8: =G8/1000 -> 4.42 | K8: =H8/1000 -> 4.433
A9: exp4_irq_thread | B9: 1 | C9: irq_thread | D9: lat_proc_dur | E9: 200 | F9: 179 | G9: 179 | H9: 183 | I9: =F9/1000 -> 0.179 | J9: =G9/1000 -> 0.179 | K9: =H9/1000 -> 0.183
A10: exp4_irq_thread | B10: 2 | C10: irq_thread | D10: lat_detect | E10: 200 | F10: 1104 | G10: 1104 | H10: 1104 | I10: =F10/1000 -> 1.104 | J10: =G10/1000 -> 1.104 | K10: =H10/1000 -> 1.104
A11: exp4_irq_thread | B11: 2 | C11: irq_thread | D11: lat_handoff | E11: 200 | F11: 3316 | G11: 3316 | H11: 3329 | I11: =F11/1000 -> 3.316 | J11: =G11/1000 -> 3.316 | K11: =H11/1000 -> 3.329
A12: exp4_irq_thread | B12: 2 | C12: irq_thread | D12: lat_process | E12: 200 | F12: 4420 | G12: 4420 | H12: 4433 | I12: =F12/1000 -> 4.42 | J12: =G12/1000 -> 4.42 | K12: =H12/1000 -> 4.433
A13: exp4_irq_thread | B13: 2 | C13: irq_thread | D13: lat_proc_dur | E13: 200 | F13: 179 | G13: 179 | H13: 183 | I13: =F13/1000 -> 0.179 | J13: =G13/1000 -> 0.179 | K13: =H13/1000 -> 0.183
... A231: exp8_workqueue_sleep | B231: 1 | C231: workqueue | D231: lat_proc_dur | E231: 50 | F231: 100976258 | G231: 100992070 | H231: 100992395 | I231: =F231/1000 -> 100976.26 | J231: =G231/1000 -> 100992.07 | K231: =H231/1000 -> 100992.4

Sheet Dados_SUM
A1: experimento | B1: execucao | C1: modo | D1: poll_ms | E1: proc_us | F1: period_ms | G1: pulse_ms | H1: gerados | I1: detectados | J1: processados | K1: cpu_x100 | L1: cpu_est_x100 | M1: janela (ms) | N1: heartbeat max (ms) | O1: perdidos | P1: perdidos (%) | Q1: CPU ocupada | R1: CPU estimada
A2: exp4_irq_thread_cpi2 | B2: 1 | C2: irq_thread | D2: 10 | E2: 0 | F2: 97 | G2: 20 | H2: 200 | I2: 200 | J2: 200 | K2: 2 | L2: 0 | M2: 19901 | O2: =MAX(0,H2-J2) -> 0 | P2: =IF(H2>0,O2/H2,0) -> 0 | Q2: =K2/10000 -> 0.0002 | R2: =L2/10000 -> 0
A3: exp4_irq_thread | B3: 1 | C3: irq_thread | D3: 10 | E3: 0 | F3: 97 | G3: 20 | H3: 200 | I3: 200 | J3: 200 | K3: 1 | L3: 0 | M3: 19901 | O3: =MAX(0,H3-J3) -> 0 | P3: =IF(H3>0,O3/H3,0) -> 0 | Q3: =K3/10000 -> 0.0001 | R3: =L3/10000 -> 0
A4: exp4_irq_thread | B4: 2 | C4: irq_thread | D4: 10 | E4: 0 | F4: 97 | G4: 20 | H4: 200 | I4: 200 | J4: 200 | K4: 1 | L4: 0 | M4: 19901 | O4: =MAX(0,H4-J4) -> 0 | P4: =IF(H4>0,O4/H4,0) -> 0 | Q4: =K4/10000 -> 0.0001 | R4: =L4/10000 -> 0
A5: exp4_irq_thread | B5: 3 | C5: irq_thread | D5: 10 | E5: 0 | F5: 97 | G5: 20 | H5: 200 | I5: 200 | J5: 200 | K5: 1 | L5: 0 | M5: 19901 | O5: =MAX(0,H5-J5) -> 0 | P5: =IF(H5>0,O5/H5,0) -> 0 | Q5: =K5/10000 -> 0.0001 | R5: =L5/10000 -> 0
A6: exp4_polling_cpi2 | B6: 1 | C6: polling | D6: 10 | E6: 0 | F6: 97 | G6: 20 | H6: 200 | I6: 200 | J6: 200 | K6: 5 | L6: 0 | M6: 19901 | O6: =MAX(0,H6-J6) -> 0 | P6: =IF(H6>0,O6/H6,0) -> 0 | Q6: =K6/10000 -> 0.0005 | R6: =L6/10000 -> 0
A7: exp4_polling_periodo95 | B7: 1 | C7: polling | D7: 10 | E7: 0 | F7: 95 | G7: 20 | H7: 200 | I7: 200 | J7: 200 | K7: 2 | L7: 0 | M7: 19501 | O7: =MAX(0,H7-J7) -> 0 | P7: =IF(H7>0,O7/H7,0) -> 0 | Q7: =K7/10000 -> 0.0002 | R7: =L7/10000 -> 0
A8: exp4_polling_periodo95 | B8: 2 | C8: polling | D8: 10 | E8: 0 | F8: 95 | G8: 20 | H8: 200 | I8: 200 | J8: 200 | K8: 2 | L8: 0 | M8: 19501 | O8: =MAX(0,H8-J8) -> 0 | P8: =IF(H8>0,O8/H8,0) -> 0 | Q8: =K8/10000 -> 0.0002 | R8: =L8/10000 -> 0
A9: exp4_polling_periodo95 | B9: 3 | C9: polling | D9: 10 | E9: 0 | F9: 95 | G9: 20 | H9: 200 | I9: 200 | J9: 200 | K9: 2 | L9: 0 | M9: 19501 | O9: =MAX(0,H9-J9) -> 0 | P9: =IF(H9>0,O9/H9,0) -> 0 | Q9: =K9/10000 -> 0.0002 | R9: =L9/10000 -> 0
A10: exp4_polling | B10: 1 | C10: polling | D10: 10 | E10: 0 | F10: 97 | G10: 20 | H10: 200 | I10: 200 | J10: 200 | K10: 2 | L10: 0 | M10: 19901 | O10: =MAX(0,H10-J10) -> 0 | P10: =IF(H10>0,O10/H10,0) -> 0 | Q10: =K10/10000 -> 0.0002 | R10: =L10/10000 -> 0
A11: exp4_polling | B11: 2 | C11: polling | D11: 10 | E11: 0 | F11: 97 | G11: 20 | H11: 200 | I11: 200 | J11: 200 | K11: 2 | L11: 0 | M11: 19901 | O11: =MAX(0,H11-J11) -> 0 | P11: =IF(H11>0,O11/H11,0) -> 0 | Q11: =K11/10000 -> 0.0002 | R11: =L11/10000 -> 0
A12: exp4_polling | B12: 3 | C12: polling | D12: 10 | E12: 0 | F12: 97 | G12: 20 | H12: 200 | I12: 200 | J12: 200 | K12: 2 | L12: 0 | M12: 19901 | O12: =MAX(0,H12-J12) -> 0 | P12: =IF(H12>0,O12/H12,0) -> 0 | Q12: =K12/10000 -> 0.0002 | R12: =L12/10000 -> 0
A13: exp4_workqueue_cpi2 | B13: 1 | C13: workqueue | D13: 10 | E13: 0 | F13: 97 | G13: 20 | H13: 200 | I13: 200 | J13: 200 | K13: 2 | L13: 0 | M13: 19901 | O13: =MAX(0,H13-J13) -> 0 | P13: =IF(H13>0,O13/H13,0) -> 0 | Q13: =K13/10000 -> 0.0002 | R13: =L13/10000 -> 0
... A57: exp6b_workqueue_saturacao | B57: 1 | C57: workqueue | D57: 10 | E57: 30000 | F57: 23 | G57: 5 | H57: 200 | I57: 200 | J57: 167 | K57: 9764 | L57: 9764 | M57: 5131 | O57: =MAX(0,H57-J57) -> 33 | P57: =IF(H57>0,O57/H57,0) -> 0.165 | Q57: =K57/10000 -> 0.9764 | R57: =L57/10000 -> 0.9764
A58: exp7_irq_thread_hb | B58: 1 | C58: irq_thread | D58: 10 | E58: 20000 | F58: 97 | G58: 20 | H58: 200 | I58: 200 | J58: 200 | K58: 1682 | L58: 1672 | M58: 23921 | N58: 2 | O58: =MAX(0,H58-J58) -> 0 | P58: =IF(H58>0,O58/H58,0) -> 0 | Q58: =K58/10000 -> 0.1682 | R58: =L58/10000 -> 0.1672
A59: exp7_isr_only_hb | B59: 1 | C59: isr_only | D59: 10 | E59: 20000 | F59: 97 | G59: 20 | H59: 200 | I59: 200 | J59: 200 | K59: 12 | L59: 1672 | M59: 23921 | N59: 21 | O59: =MAX(0,H59-J59) -> 0 | P59: =IF(H59>0,O59/H59,0) -> 0 | Q59: =K59/10000 -> 0.0012 | R59: =L59/10000 -> 0.1672
A60: exp7_workqueue_hb | B60: 1 | C60: workqueue | D60: 10 | E60: 20000 | F60: 97 | G60: 20 | H60: 200 | I60: 200 | J60: 200 | K60: 1682 | L60: 1672 | M60: 23921 | N60: 2 | O60: =MAX(0,H60-J60) -> 0 | P60: =IF(H60>0,O60/H60,0) -> 0 | Q60: =K60/10000 -> 0.1682 | R60: =L60/10000 -> 0.1672
A61: exp8_irq_thread_busy | B61: 1 | C61: irq_thread | D61: 10 | E61: 100000 | F61: 197 | G61: 20 | H61: 50 | I61: 50 | J61: 50 | K61: 4926 | L61: 4925 | M61: 10151 | O61: =MAX(0,H61-J61) -> 0 | P61: =IF(H61>0,O61/H61,0) -> 0 | Q61: =K61/10000 -> 0.4926 | R61: =L61/10000 -> 0.4925
A62: exp8_irq_thread_rajada | B62: 1 | C62: irq_thread | D62: 10 | E62: 100000 | F62: 47 | G62: 20 | H62: 50 | I62: 50 | J62: 26 | K62: 9808 | L62: 9808 | M62: 2651 | O62: =MAX(0,H62-J62) -> 24 | P62: =IF(H62>0,O62/H62,0) -> 0.48 | Q62: =K62/10000 -> 0.9808 | R62: =L62/10000 -> 0.9808
A63: exp8_irq_thread_sleep | B63: 1 | C63: irq_thread | D63: 10 | E63: 100000 | F63: 197 | G63: 20 | H63: 50 | I63: 50 | J63: 50 | K63: 0 | L63: 4974 | M63: 10151 | O63: =MAX(0,H63-J63) -> 0 | P63: =IF(H63>0,O63/H63,0) -> 0 | Q63: =K63/10000 -> 0 | R63: =L63/10000 -> 0.4974
A64: exp8_polling_busy | B64: 1 | C64: polling | D64: 10 | E64: 100000 | F64: 197 | G64: 20 | H64: 50 | I64: 50 | J64: 50 | K64: 4927 | L64: 4925 | M64: 10151 | O64: =MAX(0,H64-J64) -> 0 | P64: =IF(H64>0,O64/H64,0) -> 0 | Q64: =K64/10000 -> 0.4927 | R64: =L64/10000 -> 0.4925
A65: exp8_polling_rajada | B65: 1 | C65: polling | D65: 10 | E65: 100000 | F65: 47 | G65: 20 | H65: 50 | I65: 17 | J65: 17 | K65: 6414 | L65: 6413 | M65: 2651 | O65: =MAX(0,H65-J65) -> 33 | P65: =IF(H65>0,O65/H65,0) -> 0.66 | Q65: =K65/10000 -> 0.6414 | R65: =L65/10000 -> 0.6413
A66: exp8_polling_sleep | B66: 1 | C66: polling | D66: 10 | E66: 100000 | F66: 197 | G66: 20 | H66: 50 | I66: 50 | J66: 50 | K66: 1 | L66: 4974 | M66: 10151 | O66: =MAX(0,H66-J66) -> 0 | P66: =IF(H66>0,O66/H66,0) -> 0 | Q66: =K66/10000 -> 0.0001 | R66: =L66/10000 -> 0.4974
A67: exp8_workqueue_busy | B67: 1 | C67: workqueue | D67: 10 | E67: 100000 | F67: 197 | G67: 20 | H67: 50 | I67: 50 | J67: 50 | K67: 4926 | L67: 4925 | M67: 10151 | O67: =MAX(0,H67-J67) -> 0 | P67: =IF(H67>0,O67/H67,0) -> 0 | Q67: =K67/10000 -> 0.4926 | R67: =L67/10000 -> 0.4925
A68: exp8_workqueue_rajada | B68: 1 | C68: workqueue | D68: 10 | E68: 100000 | F68: 47 | G68: 20 | H68: 50 | I68: 50 | J68: 26 | K68: 9808 | L68: 9808 | M68: 2651 | O68: =MAX(0,H68-J68) -> 24 | P68: =IF(H68>0,O68/H68,0) -> 0.48 | Q68: =K68/10000 -> 0.9808 | R68: =L68/10000 -> 0.9808
A69: exp8_workqueue_sleep | B69: 1 | C69: workqueue | D69: 10 | E69: 100000 | F69: 197 | G69: 20 | H69: 50 | I69: 50 | J69: 50 | K69: 0 | L69: 4974 | M69: 10151 | O69: =MAX(0,H69-J69) -> 0 | P69: =IF(H69>0,O69/H69,0) -> 0 | Q69: =K69/10000 -> 0 | R69: =L69/10000 -> 0.4974

Sheet Dados_Threads
A1: experimento | B1: execucao | C1: thread | D1: pilha usada (B) | E1: pilha total (B) | F1: CPU (%) Thread Analyzer | G1: uso da pilha | H1: CPU (fracao)
A2: exp1-3_irq_thread_manual | B2: 1 | C2: worker | D2: 560 | E2: 1024 | F2: 0 | G2: =D2/E2 -> 0.546875 | H2: =F2/100 -> 0
A3: exp1-3_irq_thread_manual | B3: 1 | C3: idle | D3: 208 | E3: 1024 | F3: 99 | G3: =D3/E3 -> 0.203125 | H3: =F3/100 -> 0.99
A4: exp1-3_irq_thread_manual | B4: 1 | C4: main | D4: 928 | E4: 4096 | F4: 0 | G4: =D4/E4 -> 0.2265625 | H4: =F4/100 -> 0
A5: exp1-3_polling_manual | B5: 1 | C5: poll | D5: 576 | E5: 1024 | F5: 0 | G5: =D5/E5 -> 0.5625 | H5: =F5/100 -> 0
A6: exp1-3_polling_manual | B6: 1 | C6: idle | D6: 208 | E6: 1024 | F6: 99 | G6: =D6/E6 -> 0.203125 | H6: =F6/100 -> 0.99
A7: exp1-3_polling_manual | B7: 1 | C7: main | D7: 928 | E7: 4096 | F7: 0 | G7: =D7/E7 -> 0.2265625 | H7: =F7/100 -> 0
A8: exp1-3_polling_manual | B8: 1 | C8: ISR0 | D8: 352 | E8: 2048 | F8: 0 | G8: =D8/E8 -> 0.171875 | H8: =F8/100 -> 0
A9: exp1-3_workqueue_manual | B9: 1 | C9: sysworkq | D9: 608 | E9: 1024 | F9: 0 | G9: =D9/E9 -> 0.59375 | H9: =F9/100 -> 0
A10: exp4_irq_thread_cpi2 | B10: 1 | C10: worker | D10: 288 | E10: 1024 | F10: 0 | G10: =D10/E10 -> 0.28125 | H10: =F10/100 -> 0
A11: exp4_irq_thread_cpi2 | B11: 1 | C11: idle | D11: 208 | E11: 1024 | F11: 99 | G11: =D11/E11 -> 0.203125 | H11: =F11/100 -> 0.99
A12: exp4_irq_thread_cpi2 | B12: 1 | C12: main | D12: 1024 | E12: 4096 | F12: 0 | G12: =D12/E12 -> 0.25 | H12: =F12/100 -> 0
A13: exp4_irq_thread_cpi2 | B13: 1 | C13: ISR0 | D13: 368 | E13: 2048 | F13: 0 | G13: =D13/E13 -> 0.1796875 | H13: =F13/100 -> 0
... A283: exp8_workqueue_sleep | B283: 1 | C283: ISR0 | D283: 352 | E283: 2048 | F283: 0 | G283: =D283/E283 -> 0.171875 | H283: =F283/100 -> 0

Sheet Dados_Memoria
A1: build | B1: FLASH (B) | C1: iram0_0_seg (B) | D1: dram0_0_seg (B) | E1: .dram0.noinit - pilhas (B) | F1: RAM estatica total (B)
A2: exp1-3_irq_thread_manual | B2: 145264 | C2: 35584 | D2: 12520 | E2: 8192 | F2: =D2+E2 -> 20712
A3: exp1-3_polling_manual | B3: 145120 | C3: 35072 | D3: 12488 | E3: 8192 | F3: =D3+E3 -> 20680
A4: exp1-3_workqueue_manual | B4: 145200 | C4: 36352 | D4: 12560 | E4: 8192 | F4: =D4+E4 -> 20752
A5: exp4_irq_thread | B5: 146560 | C5: 35584 | D5: 12520 | E5: 8192 | F5: =D5+E5 -> 20712
A6: exp4_irq_thread_cpi2 | B6: 146560 | C6: 35584 | D6: 12520 | E6: 8192 | F6: =D6+E6 -> 20712
A7: exp4_polling | B7: 146416 | C7: 35072 | D7: 12488 | E7: 8192 | F7: =D7+E7 -> 20680
A8: exp4_polling_cpi2 | B8: 146416 | C8: 35072 | D8: 12488 | E8: 8192 | F8: =D8+E8 -> 20680
A9: exp4_polling_periodo95 | B9: 146416 | C9: 35072 | D9: 12488 | E9: 8192 | F9: =D9+E9 -> 20680
A10: exp4_workqueue | B10: 146496 | C10: 36352 | D10: 12560 | E10: 8192 | F10: =D10+E10 -> 20752
A11: exp4_workqueue_cpi2 | B11: 146496 | C11: 36352 | D11: 12560 | E11: 8192 | F11: =D11+E11 -> 20752
A12: exp5_poll100_pulse20 | B12: 146416 | C12: 35072 | D12: 12488 | E12: 8192 | F12: =D12+E12 -> 20680
A13: exp5_poll100_pulse5 | B13: 146416 | C13: 35072 | D13: 12488 | E13: 8192 | F13: =D13+E13 -> 20680
... A44: exp8_workqueue_sleep | B44: 146512 | C44: 36352 | D44: 12560 | E44: 8192 | F44: =D44+E44 -> 20752

Sheet Dados_Manual
A1: experimento | B1: modo | C1: toques no botao (trace) | D1: toques de 4 ms | E1: eventos processados | F1: contador a cada 10 s | G1: pilha thread evento
A2: exp1-3_irq_thread_manual | B2: irq_thread | C2: 25 | D2: 5 | E2: 25 | F2: 8 / 17 / 25 | G2: 560 / 1024
A3: exp1-3_polling_manual | B3: polling | C3: 25 | D3: 5 | E3: 22 | F3: 6 / 15 / 22 | G3: 576 / 1024
A4: exp1-3_workqueue_manual | B4: workqueue | C4: 25 | D4: 5 | E4: 25 | F4: 8 / 17 / 25 | G4: 608 / 1024

Sheet Exp1-3
A1: Experimentos 1 a 3 - modo manual (25 toques roteirizados, 30 s)
A2: Toques de 80-220 ms a cada 0,4-1,5 s; 1 a cada 5 e um toque rapido de 4 ms. Sem bounce (o botao emulado e limpo).
A4: Modo | B4: Toques gerados | C4: Toques de 4 ms | D4: Eventos processados | E4: Nao detectados | F4: Pilha da thread do evento (B)
A5: Polling | B5: =SUMIFS(Dados_Manual!$C:$C,Dados_Manual!$A:$A,"exp1-3_polling_manual") -> 25 | C5: =SUMIFS(Dados_Manual!$D:$D,Dados_Manual!$A:$A,"exp1-3_polling_manual") -> 5 | D5: =SUMIFS(Dados_Manual!$E:$E,Dados_Manual!$A:$A,"exp1-3_polling_manual") -> 22 | E5: =B5-D5 -> 3 | F5: =INDEX(Dados_Manual!$G:$G,MATCH("exp1-3_polling_manual",Dados_Manual!$A:$A,0)) -> 576 / 1024
A6: ISR + thread | B6: =SUMIFS(Dados_Manual!$C:$C,Dados_Manual!$A:$A,"exp1-3_irq_thread_manual") -> 25 | C6: =SUMIFS(Dados_Manual!$D:$D,Dados_Manual!$A:$A,"exp1-3_irq_thread_manual") -> 5 | D6: =SUMIFS(Dados_Manual!$E:$E,Dados_Manual!$A:$A,"exp1-3_irq_thread_manual") -> 25 | E6: =B6-D6 -> 0 | F6: =INDEX(Dados_Manual!$G:$G,MATCH("exp1-3_irq_thread_manual",Dados_Manual!$A:$A,0)) -> 560 / 1024
A7: ISR + work queue | B7: =SUMIFS(Dados_Manual!$C:$C,Dados_Manual!$A:$A,"exp1-3_workqueue_manual") -> 25 | C7: =SUMIFS(Dados_Manual!$D:$D,Dados_Manual!$A:$A,"exp1-3_workqueue_manual") -> 5 | D7: =SUMIFS(Dados_Manual!$E:$E,Dados_Manual!$A:$A,"exp1-3_workqueue_manual") -> 25 | E7: =B7-D7 -> 0 | F7: =INDEX(Dados_Manual!$G:$G,MATCH("exp1-3_workqueue_manual",Dados_Manual!$A:$A,0)) -> 608 / 1024

Sheet Exp4
A1: Tabela 10.1 - Tempo (us): media das 3 execucoes
A2: Padroes do Kconfig: 200 eventos, periodo 97 ms, pulso 20 ms, sem carga, polling 10 ms.
A4: Metrica | B4: Polling (P = 10 ms) | C4: ISR + thread | D4: ISR + work queue
A5: lat_detect - media | B5: =IFERROR(AVERAGEIFS(Dados_LAT!$J:$J,Dados_LAT!$A:$A,"exp4_polling",Dados_LAT!$D:$D,"lat_detect"),"sem amostras") -> 8999.92 | C5: =IFERROR(AVERAGEIFS(Dados_LAT!$J:$J,Dados_LAT!$A:$A,"exp4_irq_thread",Dados_LAT!$D:$D,"lat_detect"),"sem amostras") -> 1.104 | D5: =IFERROR(AVERAGEIFS(Dados_LAT!$J:$J,Dados_LAT!$A:$A,"exp4_workqueue",Dados_LAT!$D:$D,"lat_detect"),"sem amostras") -> 1.1
A6: lat_detect - maximo | B6: =IFERROR(_xlfn.MAXIFS(Dados_LAT!$K:$K,Dados_LAT!$A:$A,"exp4_polling",Dados_LAT!$D:$D,"lat_detect"),"sem amostras") -> 9000.008 | C6: =IFERROR(_xlfn.MAXIFS(Dados_LAT!$K:$K,Dados_LAT!$A:$A,"exp4_irq_thread",Dados_LAT!$D:$D,"lat_detect"),"sem amostras") -> 1.104 | D6: =IFERROR(_xlfn.MAXIFS(Dados_LAT!$K:$K,Dados_LAT!$A:$A,"exp4_workqueue",Dados_LAT!$D:$D,"lat_detect"),"sem amostras") -> 1.104
A7: lat_handoff - media | B7: n/a | C7: =IFERROR(AVERAGEIFS(Dados_LAT!$J:$J,Dados_LAT!$A:$A,"exp4_irq_thread",Dados_LAT!$D:$D,"lat_handoff"),"sem amostras") -> 3.316 | D7: =IFERROR(AVERAGEIFS(Dados_LAT!$J:$J,Dados_LAT!$A:$A,"exp4_workqueue",Dados_LAT!$D:$D,"lat_handoff"),"sem amostras") -> 3.929
A8: lat_handoff - maximo | B8: n/a | C8: =IFERROR(_xlfn.MAXIFS(Dados_LAT!$K:$K,Dados_LAT!$A:$A,"exp4_irq_thread",Dados_LAT!$D:$D,"lat_handoff"),"sem amostras") -> 3.329 | D8: =IFERROR(_xlfn.MAXIFS(Dados_LAT!$K:$K,Dados_LAT!$A:$A,"exp4_workqueue",Dados_LAT!$D:$D,"lat_handoff"),"sem amostras") -> 3.937
A9: lat_process - media | B9: =IFERROR(AVERAGEIFS(Dados_LAT!$J:$J,Dados_LAT!$A:$A,"exp4_polling",Dados_LAT!$D:$D,"lat_process"),"sem amostras") -> 8999.92 | C9: =IFERROR(AVERAGEIFS(Dados_LAT!$J:$J,Dados_LAT!$A:$A,"exp4_irq_thread",Dados_LAT!$D:$D,"lat_process"),"sem amostras") -> 4.42 | D9: =IFERROR(AVERAGEIFS(Dados_LAT!$J:$J,Dados_LAT!$A:$A,"exp4_workqueue",Dados_LAT!$D:$D,"lat_process"),"sem amostras") -> 5.033
A10: lat_process - maximo | B10: =IFERROR(_xlfn.MAXIFS(Dados_LAT!$K:$K,Dados_LAT!$A:$A,"exp4_polling",Dados_LAT!$D:$D,"lat_process"),"sem amostras") -> 9000.008 | C10: =IFERROR(_xlfn.MAXIFS(Dados_LAT!$K:$K,Dados_LAT!$A:$A,"exp4_irq_thread",Dados_LAT!$D:$D,"lat_process"),"sem amostras") -> 4.433 | D10: =IFERROR(_xlfn.MAXIFS(Dados_LAT!$K:$K,Dados_LAT!$A:$A,"exp4_workqueue",Dados_LAT!$D:$D,"lat_process"),"sem amostras") -> 5.041
A11: lat_proc_dur - media | B11: =IFERROR(AVERAGEIFS(Dados_LAT!$J:$J,Dados_LAT!$A:$A,"exp4_polling",Dados_LAT!$D:$D,"lat_proc_dur"),"sem amostras") -> 0.179 | C11: =IFERROR(AVERAGEIFS(Dados_LAT!$J:$J,Dados_LAT!$A:$A,"exp4_irq_thread",Dados_LAT!$D:$D,"lat_proc_dur"),"sem amostras") -> 0.179 | D11: =IFERROR(AVERAGEIFS(Dados_LAT!$J:$J,Dados_LAT!$A:$A,"exp4_workqueue",Dados_LAT!$D:$D,"lat_proc_dur"),"sem amostras") -> 0.179
A12: Jitter de lat_process (max - min) | B12: =_xlfn.MAXIFS(Dados_LAT!$K:$K,Dados_LAT!$A:$A,"exp4_polling",Dados_LAT!$D:$D,"lat_process")-_xlfn.MINIFS(Dados_LAT!$I:$I,Dados_LAT!$A:$A,"exp4_polling",Dados_LAT!$D:$D,"lat_process") -> 16.15 | C12: =_xlfn.MAXIFS(Dados_LAT!$K:$K,Dados_LAT!$A:$A,"exp4_irq_thread",Dados_LAT!$D:$D,"lat_process")-_xlfn.MINIFS(Dados_LAT!$I:$I,Dados_LAT!$A:$A,"exp4_irq_thread",Dados_LAT!$D:$D,"lat_process") -> 0.013 | D12: =_xlfn.MAXIFS(Dados_LAT!$K:$K,Dados_LAT!$A:$A,"exp4_workqueue",Dados_LAT!$D:$D,"lat_process")-_xlfn.MINIFS(Dados_LAT!$I:$I,Dados_LAT!$A:$A,"exp4_workqueue",Dados_LAT!$D:$D,"lat_process") -> 0.008
A13: Amplitude da media de lat_process entre as 3 execucoes | B13: =_xlfn.MAXIFS(Dados_LAT!$J:$J,Dados_LAT!$A:$A,"exp4_polling",Dados_LAT!$D:$D,"lat_process")-_xlfn.MINIFS(Dados_LAT!$J:$J,Dados_LAT!$A:$A,"exp4_polling",Dados_LAT!$D:$D,"lat_process") -> 0 | C13: =_xlfn.MAXIFS(Dados_LAT!$J:$J,Dados_LAT!$A:$A,"exp4_irq_thread",Dados_LAT!$D:$D,"lat_process")-_xlfn.MINIFS(Dados_LAT!$J:$J,Dados_LAT!$A:$A,"exp4_irq_thread",Dados_LAT!$D:$D,"lat_process") -> 0 | D13: =_xlfn.MAXIFS(Dados_LAT!$J:$J,Dados_LAT!$A:$A,"exp4_workqueue",Dados_LAT!$D:$D,"lat_process")-_xlfn.MINIFS(Dados_LAT!$J:$J,Dados_LAT!$A:$A,"exp4_workqueue",Dados_LAT!$D:$D,"lat_process") -> 0
A15: Tabela 10.1b - Polling com estimulo fora de fase e sensibilidade ao CPI
A16: Periodo 95 ms = 97 ticks reais (k_msleep arredonda +1 tick). CPI~2: -icount shift=3 (8 ns/instrucao), 1 execucao.
A18: Metrica (us) | B18: Polling, periodo 95 ms | C18: Polling CPI~2 | D18: ISR + thread CPI~2 | E18: ISR + work queue CPI~2
A19: lat_detect - media | B19: =IFERROR(AVERAGEIFS(Dados_LAT!$J:$J,Dados_LAT!$A:$A,"exp4_polling_periodo95",Dados_LAT!$D:$D,"lat_detect"),"sem amostras") -> 6029.408 | C19: =IFERROR(AVERAGEIFS(Dados_LAT!$J:$J,Dados_LAT!$A:$A,"exp4_polling_cpi2",Dados_LAT!$D:$D,"lat_detect"),"sem amostras") -> 8999.845 | D19: =IFERROR(AVERAGEIFS(Dados_LAT!$J:$J,Dados_LAT!$A:$A,"exp4_irq_thread_cpi2",Dados_LAT!$D:$D,"lat_detect"),"sem amostras") -> 2.204 | E19: =IFERROR(AVERAGEIFS(Dados_LAT!$J:$J,Dados_LAT!$A:$A,"exp4_workqueue_cpi2",Dados_LAT!$D:$D,"lat_detect"),"sem amostras") -> 2.204
A20: lat_detect - maximo | B20: =IFERROR(_xlfn.MAXIFS(Dados_LAT!$K:$K,Dados_LAT!$A:$A,"exp4_polling_periodo95",Dados_LAT!$D:$D,"lat_detect"),"sem amostras") -> 10994.308 | C20: =IFERROR(_xlfn.MAXIFS(Dados_LAT!$K:$K,Dados_LAT!$A:$A,"exp4_polling_cpi2",Dados_LAT!$D:$D,"lat_detect"),"sem amostras") -> 9000.012 | D20: =IFERROR(_xlfn.MAXIFS(Dados_LAT!$K:$K,Dados_LAT!$A:$A,"exp4_irq_thread_cpi2",Dados_LAT!$D:$D,"lat_detect"),"sem amostras") -> 2.208 | E20: =IFERROR(_xlfn.MAXIFS(Dados_LAT!$K:$K,Dados_LAT!$A:$A,"exp4_workqueue_cpi2",Dados_LAT!$D:$D,"lat_detect"),"sem amostras") -> 2.208
A21: lat_handoff - media | B21: n/a | C21: n/a | D21: =IFERROR(AVERAGEIFS(Dados_LAT!$J:$J,Dados_LAT!$A:$A,"exp4_irq_thread_cpi2",Dados_LAT!$D:$D,"lat_handoff"),"sem amostras") -> 6.637 | E21: =IFERROR(AVERAGEIFS(Dados_LAT!$J:$J,Dados_LAT!$A:$A,"exp4_workqueue_cpi2",Dados_LAT!$D:$D,"lat_handoff"),"sem amostras") -> 7.862
A22: lat_handoff - maximo | B22: n/a | C22: n/a | D22: =IFERROR(_xlfn.MAXIFS(Dados_LAT!$K:$K,Dados_LAT!$A:$A,"exp4_irq_thread_cpi2",Dados_LAT!$D:$D,"lat_handoff"),"sem amostras") -> 6.658 | E22: =IFERROR(_xlfn.MAXIFS(Dados_LAT!$K:$K,Dados_LAT!$A:$A,"exp4_workqueue_cpi2",Dados_LAT!$D:$D,"lat_handoff"),"sem amostras") -> 7.879
A23: lat_process - media | B23: =IFERROR(AVERAGEIFS(Dados_LAT!$J:$J,Dados_LAT!$A:$A,"exp4_polling_periodo95",Dados_LAT!$D:$D,"lat_process"),"sem amostras") -> 6029.408 | C23: =IFERROR(AVERAGEIFS(Dados_LAT!$J:$J,Dados_LAT!$A:$A,"exp4_polling_cpi2",Dados_LAT!$D:$D,"lat_process"),"sem amostras") -> 8999.845 | D23: =IFERROR(AVERAGEIFS(Dados_LAT!$J:$J,Dados_LAT!$A:$A,"exp4_irq_thread_cpi2",Dados_LAT!$D:$D,"lat_process"),"sem amostras") -> 8.845 | E23: =IFERROR(AVERAGEIFS(Dados_LAT!$J:$J,Dados_LAT!$A:$A,"exp4_workqueue_cpi2",Dados_LAT!$D:$D,"lat_process"),"sem amostras") -> 10.07
A24: lat_process - maximo | B24: =IFERROR(_xlfn.MAXIFS(Dados_LAT!$K:$K,Dados_LAT!$A:$A,"exp4_polling_periodo95",Dados_LAT!$D:$D,"lat_process"),"sem amostras") -> 10994.308 | C24: =IFERROR(_xlfn.MAXIFS(Dados_LAT!$K:$K,Dados_LAT!$A:$A,"exp4_polling_cpi2",Dados_LAT!$D:$D,"lat_process"),"sem amostras") -> 9000.012 | D24: =IFERROR(_xlfn.MAXIFS(Dados_LAT!$K:$K,Dados_LAT!$A:$A,"exp4_irq_thread_cpi2",Dados_LAT!$D:$D,"lat_process"),"sem amostras") -> 8.866 | E24: =IFERROR(_xlfn.MAXIFS(Dados_LAT!$K:$K,Dados_LAT!$A:$A,"exp4_workqueue_cpi2",Dados_LAT!$D:$D,"lat_process"),"sem amostras") -> 10.087
A26: Tabela 10.2 - Eventos (media das 3 execucoes)
A28: Metrica | B28: Polling | C28: ISR + thread | D28: ISR + work queue
A29: Gerados | B29: =IFERROR(AVERAGEIFS(Dados_SUM!$H:$H,Dados_SUM!$A:$A,"exp4_polling"),"sem amostras") -> 200 | C29: =IFERROR(AVERAGEIFS(Dados_SUM!$H:$H,Dados_SUM!$A:$A,"exp4_irq_thread"),"sem amostras") -> 200 | D29: =IFERROR(AVERAGEIFS(Dados_SUM!$H:$H,Dados_SUM!$A:$A,"exp4_workqueue"),"sem amostras") -> 200
A30: Detectados | B30: =IFERROR(AVERAGEIFS(Dados_SUM!$I:$I,Dados_SUM!$A:$A,"exp4_polling"),"sem amostras") -> 200 | C30: =IFERROR(AVERAGEIFS(Dados_SUM!$I:$I,Dados_SUM!$A:$A,"exp4_irq_thread"),"sem amostras") -> 200 | D30: =IFERROR(AVERAGEIFS(Dados_SUM!$I:$I,Dados_SUM!$A:$A,"exp4_workqueue"),"sem amostras") -> 200
A31: Processados | B31: =IFERROR(AVERAGEIFS(Dados_SUM!$J:$J,Dados_SUM!$A:$A,"exp4_polling"),"sem amostras") -> 200 | C31: =IFERROR(AVERAGEIFS(Dados_SUM!$J:$J,Dados_SUM!$A:$A,"exp4_irq_thread"),"sem amostras") -> 200 | D31: =IFERROR(AVERAGEIFS(Dados_SUM!$J:$J,Dados_SUM!$A:$A,"exp4_workqueue"),"sem amostras") -> 200
A32: Perdidos | B32: =IFERROR(AVERAGEIFS(Dados_SUM!$O:$O,Dados_SUM!$A:$A,"exp4_polling"),"sem amostras") -> 0 | C32: =IFERROR(AVERAGEIFS(Dados_SUM!$O:$O,Dados_SUM!$A:$A,"exp4_irq_thread"),"sem amostras") -> 0 | D32: =IFERROR(AVERAGEIFS(Dados_SUM!$O:$O,Dados_SUM!$A:$A,"exp4_workqueue"),"sem amostras") -> 0
A34: Tabela 10.3 - CPU (media das 3 execucoes)
A36: Metrica | B36: Polling | C36: ISR + thread | D36: ISR + work queue
A37: CPU ocupada (kernel) | B37: =IFERROR(AVERAGEIFS(Dados_SUM!$Q:$Q,Dados_SUM!$A:$A,"exp4_polling"),"sem amostras") -> 0.0002 | C37: =IFERROR(AVERAGEIFS(Dados_SUM!$Q:$Q,Dados_SUM!$A:$A,"exp4_irq_thread"),"sem amostras") -> 0.0001 | D37: =IFERROR(AVERAGEIFS(Dados_SUM!$Q:$Q,Dados_SUM!$A:$A,"exp4_workqueue"),"sem amostras") -> 0.0001
A38: CPU estimada (processamento) | B38: =IFERROR(AVERAGEIFS(Dados_SUM!$R:$R,Dados_SUM!$A:$A,"exp4_polling"),"sem amostras") -> 0 | C38: =IFERROR(AVERAGEIFS(Dados_SUM!$R:$R,Dados_SUM!$A:$A,"exp4_irq_thread"),"sem amostras") -> 0 | D38: =IFERROR(AVERAGEIFS(Dados_SUM!$R:$R,Dados_SUM!$A:$A,"exp4_workqueue"),"sem amostras") -> 0
A39: idle (Thread Analyzer) | B39: =IFERROR(AVERAGEIFS(Dados_Threads!$H:$H,Dados_Threads!$A:$A,"exp4_polling",Dados_Threads!$C:$C,"idle"),"sem amostras") -> 0.99 | C39: =IFERROR(AVERAGEIFS(Dados_Threads!$H:$H,Dados_Threads!$A:$A,"exp4_irq_thread",Dados_Threads!$C:$C,"idle"),"sem amostras") -> 0.99 | D39: =IFERROR(AVERAGEIFS(Dados_Threads!$H:$H,Dados_Threads!$A:$A,"exp4_workqueue",Dados_Threads!$C:$C,"idle"),"sem amostras") -> 0.99
A40: Thread do evento (poll/worker/sysworkq) | B40: =IFERROR(AVERAGEIFS(Dados_Threads!$H:$H,Dados_Threads!$A:$A,"exp4_polling",Dados_Threads!$C:$C,"poll"),"sem amostras") -> 0 | C40: =IFERROR(AVERAGEIFS(Dados_Threads!$H:$H,Dados_Threads!$A:$A,"exp4_irq_thread",Dados_Threads!$C:$C,"worker"),"sem amostras") -> 0 | D40: =IFERROR(AVERAGEIFS(Dados_Threads!$H:$H,Dados_Threads!$A:$A,"exp4_workqueue",Dados_Threads!$C:$C,"sysworkq"),"sem amostras") -> 0
A41: main (gerador de estimulo) | B41: =IFERROR(AVERAGEIFS(Dados_Threads!$H:$H,Dados_Threads!$A:$A,"exp4_polling",Dados_Threads!$C:$C,"main"),"sem amostras") -> 0 | C41: =IFERROR(AVERAGEIFS(Dados_Threads!$H:$H,Dados_Threads!$A:$A,"exp4_irq_thread",Dados_Threads!$C:$C,"main"),"sem amostras") -> 0 | D41: =IFERROR(AVERAGEIFS(Dados_Threads!$H:$H,Dados_Threads!$A:$A,"exp4_workqueue",Dados_Threads!$C:$C,"main"),"sem amostras") -> 0
A43: Tabela 10.4 - Memoria
A44: Flash = regiao FLASH do resumo do build. RAM = dram0_0_seg (dados+bss) + .dram0.noinit (pilhas, contadas na regiao dram1 do resumo). Pilhas: Thread Analyzer (usada / total).
A46: Metrica | B46: Polling | C46: ISR + thread | D46: ISR + work queue
A47: Flash usada (bytes) | B47: =INDEX(Dados_Memoria!$B:$B,MATCH("exp4_polling",Dados_Memoria!$A:$A,0)) -> 146416 | C47: =INDEX(Dados_Memoria!$B:$B,MATCH("exp4_irq_thread",Dados_Memoria!$A:$A,0)) -> 146560 | D47: =INDEX(Dados_Memoria!$B:$B,MATCH("exp4_workqueue",Dados_Memoria!$A:$A,0)) -> 146496
A48: RAM dram0_0_seg - dados + bss (bytes) | B48: =INDEX(Dados_Memoria!$D:$D,MATCH("exp4_polling",Dados_Memoria!$A:$A,0)) -> 12488 | C48: =INDEX(Dados_Memoria!$D:$D,MATCH("exp4_irq_thread",Dados_Memoria!$A:$A,0)) -> 12520 | D48: =INDEX(Dados_Memoria!$D:$D,MATCH("exp4_workqueue",Dados_Memoria!$A:$A,0)) -> 12560
A49: RAM .dram0.noinit - pilhas de todas as threads (bytes) | B49: =INDEX(Dados_Memoria!$E:$E,MATCH("exp4_polling",Dados_Memoria!$A:$A,0)) -> 8192 | C49: =INDEX(Dados_Memoria!$E:$E,MATCH("exp4_irq_thread",Dados_Memoria!$A:$A,0)) -> 8192 | D49: =INDEX(Dados_Memoria!$E:$E,MATCH("exp4_workqueue",Dados_Memoria!$A:$A,0)) -> 8192
...

Sheet Exp5
A1: Tabela 11.1 - Varredura do periodo de polling (media de 3 execucoes)
A2: Periodo do estimulo 95 ms (97 ticks reais) para varrer todas as fases do polling.
A4: P (ms) | B4: Pulso (ms) | C4: Lat. media (us) | D4: Lat. max (us) | E4: CPU ocupada | F4: Detectados | G4: Gerados | H4: Perdidos (%)
A5: 1 | B5: 20 | C5: =IFERROR(AVERAGEIFS(Dados_LAT!$J:$J,Dados_LAT!$A:$A,"exp5_poll1_pulse20",Dados_LAT!$D:$D,"lat_detect"),"sem amostras") -> 1497.07 | D5: =IFERROR(_xlfn.MAXIFS(Dados_LAT!$K:$K,Dados_LAT!$A:$A,"exp5_poll1_pulse20",Dados_LAT!$D:$D,"lat_detect"),"sem amostras") -> 1994.308 | E5: =IFERROR(AVERAGEIFS(Dados_SUM!$Q:$Q,Dados_SUM!$A:$A,"exp5_poll1_pulse20"),"sem amostras") -> 0.0012 | F5: =IFERROR(AVERAGEIFS(Dados_SUM!$I:$I,Dados_SUM!$A:$A,"exp5_poll1_pulse20"),"sem amostras") -> 200 | G5: =IFERROR(AVERAGEIFS(Dados_SUM!$H:$H,Dados_SUM!$A:$A,"exp5_poll1_pulse20"),"sem amostras") -> 200 | H5: =IFERROR(AVERAGEIFS(Dados_SUM!$P:$P,Dados_SUM!$A:$A,"exp5_poll1_pulse20"),"sem amostras") -> 0
A6: 5 | B6: 20 | C6: =IFERROR(AVERAGEIFS(Dados_LAT!$J:$J,Dados_LAT!$A:$A,"exp5_poll5_pulse20",Dados_LAT!$D:$D,"lat_detect"),"sem amostras") -> 3478.979 | D6: =IFERROR(_xlfn.MAXIFS(Dados_LAT!$K:$K,Dados_LAT!$A:$A,"exp5_poll5_pulse20",Dados_LAT!$D:$D,"lat_detect"),"sem amostras") -> 5994.308 | E6: =IFERROR(AVERAGEIFS(Dados_SUM!$Q:$Q,Dados_SUM!$A:$A,"exp5_poll5_pulse20"),"sem amostras") -> 0.0004 | F6: =IFERROR(AVERAGEIFS(Dados_SUM!$I:$I,Dados_SUM!$A:$A,"exp5_poll5_pulse20"),"sem amostras") -> 200 | G6: =IFERROR(AVERAGEIFS(Dados_SUM!$H:$H,Dados_SUM!$A:$A,"exp5_poll5_pulse20"),"sem amostras") -> 200 | H6: =IFERROR(AVERAGEIFS(Dados_SUM!$P:$P,Dados_SUM!$A:$A,"exp5_poll5_pulse20"),"sem amostras") -> 0
A7: 10 | B7: 20 | C7: =IFERROR(AVERAGEIFS(Dados_LAT!$J:$J,Dados_LAT!$A:$A,"exp5_poll10_pulse20",Dados_LAT!$D:$D,"lat_detect"),"sem amostras") -> 6029.408 | D7: =IFERROR(_xlfn.MAXIFS(Dados_LAT!$K:$K,Dados_LAT!$A:$A,"exp5_poll10_pulse20",Dados_LAT!$D:$D,"lat_detect"),"sem amostras") -> 10994.308 | E7: =IFERROR(AVERAGEIFS(Dados_SUM!$Q:$Q,Dados_SUM!$A:$A,"exp5_poll10_pulse20"),"sem amostras") -> 0.0002 | F7: =IFERROR(AVERAGEIFS(Dados_SUM!$I:$I,Dados_SUM!$A:$A,"exp5_poll10_pulse20"),"sem amostras") -> 200 | G7: =IFERROR(AVERAGEIFS(Dados_SUM!$H:$H,Dados_SUM!$A:$A,"exp5_poll10_pulse20"),"sem amostras") -> 200 | H7: =IFERROR(AVERAGEIFS(Dados_SUM!$P:$P,Dados_SUM!$A:$A,"exp5_poll10_pulse20"),"sem amostras") -> 0
A8: 50 | B8: 20 | C8: =IFERROR(AVERAGEIFS(Dados_LAT!$J:$J,Dados_LAT!$A:$A,"exp5_poll50_pulse20",Dados_LAT!$D:$D,"lat_detect"),"sem amostras") -> 10875.058 | D8: =IFERROR(_xlfn.MAXIFS(Dados_LAT!$K:$K,Dados_LAT!$A:$A,"exp5_poll50_pulse20",Dados_LAT!$D:$D,"lat_detect"),"sem amostras") -> 21001.508 | E8: =IFERROR(AVERAGEIFS(Dados_SUM!$Q:$Q,Dados_SUM!$A:$A,"exp5_poll50_pulse20"),"sem amostras") -> 0 | F8: =IFERROR(AVERAGEIFS(Dados_SUM!$I:$I,Dados_SUM!$A:$A,"exp5_poll50_pulse20"),"sem amostras") -> 80 | G8: =IFERROR(AVERAGEIFS(Dados_SUM!$H:$H,Dados_SUM!$A:$A,"exp5_poll50_pulse20"),"sem amostras") -> 200 | H8: =IFERROR(AVERAGEIFS(Dados_SUM!$P:$P,Dados_SUM!$A:$A,"exp5_poll50_pulse20"),"sem amostras") -> 0.6
A9: 100 | B9: 20 | C9: =IFERROR(AVERAGEIFS(Dados_LAT!$J:$J,Dados_LAT!$A:$A,"exp5_poll100_pulse20",Dados_LAT!$D:$D,"lat_detect"),"sem amostras") -> 4442.65 | D9: =IFERROR(_xlfn.MAXIFS(Dados_LAT!$K:$K,Dados_LAT!$A:$A,"exp5_poll100_pulse20",Dados_LAT!$D:$D,"lat_detect"),"sem amostras") -> 19983.854 | E9: =IFERROR(AVERAGEIFS(Dados_SUM!$Q:$Q,Dados_SUM!$A:$A,"exp5_poll100_pulse20"),"sem amostras") -> 0 | F9: =IFERROR(AVERAGEIFS(Dados_SUM!$I:$I,Dados_SUM!$A:$A,"exp5_poll100_pulse20"),"sem amostras") -> 9 | G9: =IFERROR(AVERAGEIFS(Dados_SUM!$H:$H,Dados_SUM!$A:$A,"exp5_poll100_pulse20"),"sem amostras") -> 200 | H9: =IFERROR(AVERAGEIFS(Dados_SUM!$P:$P,Dados_SUM!$A:$A,"exp5_poll100_pulse20"),"sem amostras") -> 0.955
A10: 1 | B10: 5 | C10: =IFERROR(AVERAGEIFS(Dados_LAT!$J:$J,Dados_LAT!$A:$A,"exp5_poll1_pulse5",Dados_LAT!$D:$D,"lat_detect"),"sem amostras") -> 1497.075 | D10: =IFERROR(_xlfn.MAXIFS(Dados_LAT!$K:$K,Dados_LAT!$A:$A,"exp5_poll1_pulse5",Dados_LAT!$D:$D,"lat_detect"),"sem amostras") -> 1994.308 | E10: =IFERROR(AVERAGEIFS(Dados_SUM!$Q:$Q,Dados_SUM!$A:$A,"exp5_poll1_pulse5"),"sem amostras") -> 0.0012 | F10: =IFERROR(AVERAGEIFS(Dados_SUM!$I:$I,Dados_SUM!$A:$A,"exp5_poll1_pulse5"),"sem amostras") -> 200 | G10: =IFERROR(AVERAGEIFS(Dados_SUM!$H:$H,Dados_SUM!$A:$A,"exp5_poll1_pulse5"),"sem amostras") -> 200 | H10: =IFERROR(AVERAGEIFS(Dados_SUM!$P:$P,Dados_SUM!$A:$A,"exp5_poll1_pulse5"),"sem amostras") -> 0
A11: 5 | B11: 5 | C11: =IFERROR(AVERAGEIFS(Dados_LAT!$J:$J,Dados_LAT!$A:$A,"exp5_poll5_pulse5",Dados_LAT!$D:$D,"lat_detect"),"sem amostras") -> 3479.229 | D11: =IFERROR(_xlfn.MAXIFS(Dados_LAT!$K:$K,Dados_LAT!$A:$A,"exp5_poll5_pulse5",Dados_LAT!$D:$D,"lat_detect"),"sem amostras") -> 5995.82 | E11: =IFERROR(AVERAGEIFS(Dados_SUM!$Q:$Q,Dados_SUM!$A:$A,"exp5_poll5_pulse5"),"sem amostras") -> 0.0004 | F11: =IFERROR(AVERAGEIFS(Dados_SUM!$I:$I,Dados_SUM!$A:$A,"exp5_poll5_pulse5"),"sem amostras") -> 200 | G11: =IFERROR(AVERAGEIFS(Dados_SUM!$H:$H,Dados_SUM!$A:$A,"exp5_poll5_pulse5"),"sem amostras") -> 200 | H11: =IFERROR(AVERAGEIFS(Dados_SUM!$P:$P,Dados_SUM!$A:$A,"exp5_poll5_pulse5"),"sem amostras") -> 0
A12: 10 | B12: 5 | C12: =IFERROR(AVERAGEIFS(Dados_LAT!$J:$J,Dados_LAT!$A:$A,"exp5_poll10_pulse5",Dados_LAT!$D:$D,"lat_detect"),"sem amostras") -> 3500.254 | D12: =IFERROR(_xlfn.MAXIFS(Dados_LAT!$K:$K,Dados_LAT!$A:$A,"exp5_poll10_pulse5",Dados_LAT!$D:$D,"lat_detect"),"sem amostras") -> 6001.516 | E12: =IFERROR(AVERAGEIFS(Dados_SUM!$Q:$Q,Dados_SUM!$A:$A,"exp5_poll10_pulse5"),"sem amostras") -> 0.0002 | F12: =IFERROR(AVERAGEIFS(Dados_SUM!$I:$I,Dados_SUM!$A:$A,"exp5_poll10_pulse5"),"sem amostras") -> 108 | G12: =IFERROR(AVERAGEIFS(Dados_SUM!$H:$H,Dados_SUM!$A:$A,"exp5_poll10_pulse5"),"sem amostras") -> 200 | H12: =IFERROR(AVERAGEIFS(Dados_SUM!$P:$P,Dados_SUM!$A:$A,"exp5_poll10_pulse5"),"sem amostras") -> 0.46
A13: 50 | B13: 5 | C13: =IFERROR(AVERAGEIFS(Dados_LAT!$J:$J,Dados_LAT!$A:$A,"exp5_poll50_pulse5",Dados_LAT!$D:$D,"lat_detect"),"sem amostras") -> 3391.504 | D13: =IFERROR(_xlfn.MAXIFS(Dados_LAT!$K:$K,Dados_LAT!$A:$A,"exp5_poll50_pulse5",Dados_LAT!$D:$D,"lat_detect"),"sem amostras") -> 6001.516 | E13: =IFERROR(AVERAGEIFS(Dados_SUM!$Q:$Q,Dados_SUM!$A:$A,"exp5_poll50_pulse5"),"sem amostras") -> 0 | F13: =IFERROR(AVERAGEIFS(Dados_SUM!$I:$I,Dados_SUM!$A:$A,"exp5_poll50_pulse5"),"sem amostras") -> 23 | G13: =IFERROR(AVERAGEIFS(Dados_SUM!$H:$H,Dados_SUM!$A:$A,"exp5_poll50_pulse5"),"sem amostras") -> 200 | H13: =IFERROR(AVERAGEIFS(Dados_SUM!$P:$P,Dados_SUM!$A:$A,"exp5_poll50_pulse5"),"sem amostras") -> 0.885
A14: 100 | B14: 5 | C14: =IFERROR(AVERAGEIFS(Dados_LAT!$J:$J,Dados_LAT!$A:$A,"exp5_poll100_pulse5",Dados_LAT!$D:$D,"lat_detect"),"sem amostras") -> 2500 | D14: =IFERROR(_xlfn.MAXIFS(Dados_LAT!$K:$K,Dados_LAT!$A:$A,"exp5_poll100_pulse5",Dados_LAT!$D:$D,"lat_detect"),"sem amostras") -> 4000.004 | E14: =IFERROR(AVERAGEIFS(Dados_SUM!$Q:$Q,Dados_SUM!$A:$A,"exp5_poll100_pulse5"),"sem amostras") -> 0 | F14: =IFERROR(AVERAGEIFS(Dados_SUM!$I:$I,Dados_SUM!$A:$A,"exp5_poll100_pulse5"),"sem amostras") -> 8 | G14: =IFERROR(AVERAGEIFS(Dados_SUM!$H:$H,Dados_SUM!$A:$A,"exp5_poll100_pulse5"),"sem amostras") -> 200 | H14: =IFERROR(AVERAGEIFS(Dados_SUM!$P:$P,Dados_SUM!$A:$A,"exp5_poll100_pulse5"),"sem amostras") -> 0.96

Sheet Exp6
A1: Tabela 12.1 - Carga por evento (periodo do estimulo = 97 ms)
A3: Carga (us) | B3: Modo | C3: CPU ocupada | D3: CPU estimada | E3: Lat. process media (us) | F3: Perdidos
A4: 0 | B4: ISR + thread | C4: =IFERROR(AVERAGEIFS(Dados_SUM!$Q:$Q,Dados_SUM!$A:$A,"exp6a_irq_thread_proc0"),"sem amostras") -> 0.0001 | D4: =IFERROR(AVERAGEIFS(Dados_SUM!$R:$R,Dados_SUM!$A:$A,"exp6a_irq_thread_proc0"),"sem amostras") -> 0 | E4: =IFERROR(AVERAGEIFS(Dados_LAT!$J:$J,Dados_LAT!$A:$A,"exp6a_irq_thread_proc0",Dados_LAT!$D:$D,"lat_process"),"sem amostras") -> 4.42 | F4: =IFERROR(AVERAGEIFS(Dados_SUM!$O:$O,Dados_SUM!$A:$A,"exp6a_irq_thread_proc0"),"sem amostras") -> 0
A5: 0 | B5: ISR + work queue | C5: =IFERROR(AVERAGEIFS(Dados_SUM!$Q:$Q,Dados_SUM!$A:$A,"exp6a_workqueue_proc0"),"sem amostras") -> 0.0001 | D5: =IFERROR(AVERAGEIFS(Dados_SUM!$R:$R,Dados_SUM!$A:$A,"exp6a_workqueue_proc0"),"sem amostras") -> 0 | E5: =IFERROR(AVERAGEIFS(Dados_LAT!$J:$J,Dados_LAT!$A:$A,"exp6a_workqueue_proc0",Dados_LAT!$D:$D,"lat_process"),"sem amostras") -> 5.033 | F5: =IFERROR(AVERAGEIFS(Dados_SUM!$O:$O,Dados_SUM!$A:$A,"exp6a_workqueue_proc0"),"sem amostras") -> 0
A6: 1000 | B6: ISR + thread | C6: =IFERROR(AVERAGEIFS(Dados_SUM!$Q:$Q,Dados_SUM!$A:$A,"exp6a_irq_thread_proc1000"),"sem amostras") -> 0.01 | D6: =IFERROR(AVERAGEIFS(Dados_SUM!$R:$R,Dados_SUM!$A:$A,"exp6a_irq_thread_proc1000"),"sem amostras") -> 0.0099 | E6: =IFERROR(AVERAGEIFS(Dados_LAT!$J:$J,Dados_LAT!$A:$A,"exp6a_irq_thread_proc1000",Dados_LAT!$D:$D,"lat_process"),"sem amostras") -> 4.42 | F6: =IFERROR(AVERAGEIFS(Dados_SUM!$O:$O,Dados_SUM!$A:$A,"exp6a_irq_thread_proc1000"),"sem amostras") -> 0
A7: 1000 | B7: ISR + work queue | C7: =IFERROR(AVERAGEIFS(Dados_SUM!$Q:$Q,Dados_SUM!$A:$A,"exp6a_workqueue_proc1000"),"sem amostras") -> 0.01 | D7: =IFERROR(AVERAGEIFS(Dados_SUM!$R:$R,Dados_SUM!$A:$A,"exp6a_workqueue_proc1000"),"sem amostras") -> 0.0099 | E7: =IFERROR(AVERAGEIFS(Dados_LAT!$J:$J,Dados_LAT!$A:$A,"exp6a_workqueue_proc1000",Dados_LAT!$D:$D,"lat_process"),"sem amostras") -> 5.033 | F7: =IFERROR(AVERAGEIFS(Dados_SUM!$O:$O,Dados_SUM!$A:$A,"exp6a_workqueue_proc1000"),"sem amostras") -> 0
A8: 10000 | B8: ISR + thread | C8: =IFERROR(AVERAGEIFS(Dados_SUM!$Q:$Q,Dados_SUM!$A:$A,"exp6a_irq_thread_proc10000"),"sem amostras") -> 0.0913 | D8: =IFERROR(AVERAGEIFS(Dados_SUM!$R:$R,Dados_SUM!$A:$A,"exp6a_irq_thread_proc10000"),"sem amostras") -> 0.0912 | E8: =IFERROR(AVERAGEIFS(Dados_LAT!$J:$J,Dados_LAT!$A:$A,"exp6a_irq_thread_proc10000",Dados_LAT!$D:$D,"lat_process"),"sem amostras") -> 4.42 | F8: =IFERROR(AVERAGEIFS(Dados_SUM!$O:$O,Dados_SUM!$A:$A,"exp6a_irq_thread_proc10000"),"sem amostras") -> 0
A9: 10000 | B9: ISR + work queue | C9: =IFERROR(AVERAGEIFS(Dados_SUM!$Q:$Q,Dados_SUM!$A:$A,"exp6a_workqueue_proc10000"),"sem amostras") -> 0.0913 | D9: =IFERROR(AVERAGEIFS(Dados_SUM!$R:$R,Dados_SUM!$A:$A,"exp6a_workqueue_proc10000"),"sem amostras") -> 0.0912 | E9: =IFERROR(AVERAGEIFS(Dados_LAT!$J:$J,Dados_LAT!$A:$A,"exp6a_workqueue_proc10000",Dados_LAT!$D:$D,"lat_process"),"sem amostras") -> 5.033 | F9: =IFERROR(AVERAGEIFS(Dados_SUM!$O:$O,Dados_SUM!$A:$A,"exp6a_workqueue_proc10000"),"sem amostras") -> 0
A10: 50000 | B10: ISR + thread | C10: =IFERROR(AVERAGEIFS(Dados_SUM!$Q:$Q,Dados_SUM!$A:$A,"exp6a_irq_thread_proc50000"),"sem amostras") -> 0.3339 | D10: =IFERROR(AVERAGEIFS(Dados_SUM!$R:$R,Dados_SUM!$A:$A,"exp6a_irq_thread_proc50000"),"sem amostras") -> 0.3338 | E10: =IFERROR(AVERAGEIFS(Dados_LAT!$J:$J,Dados_LAT!$A:$A,"exp6a_irq_thread_proc50000",Dados_LAT!$D:$D,"lat_process"),"sem amostras") -> 4.425 | F10: =IFERROR(AVERAGEIFS(Dados_SUM!$O:$O,Dados_SUM!$A:$A,"exp6a_irq_thread_proc50000"),"sem amostras") -> 0
A11: 50000 | B11: ISR + work queue | C11: =IFERROR(AVERAGEIFS(Dados_SUM!$Q:$Q,Dados_SUM!$A:$A,"exp6a_workqueue_proc50000"),"sem amostras") -> 0.3339 | D11: =IFERROR(AVERAGEIFS(Dados_SUM!$R:$R,Dados_SUM!$A:$A,"exp6a_workqueue_proc50000"),"sem amostras") -> 0.3338 | E11: =IFERROR(AVERAGEIFS(Dados_LAT!$J:$J,Dados_LAT!$A:$A,"exp6a_workqueue_proc50000",Dados_LAT!$D:$D,"lat_process"),"sem amostras") -> 5.033 | F11: =IFERROR(AVERAGEIFS(Dados_SUM!$O:$O,Dados_SUM!$A:$A,"exp6a_workqueue_proc50000"),"sem amostras") -> 0
A14: Tabela 12.2 - Saturacao (tratamento 30 ms > periodo 23 ms; main prioridade 0)
A16: Modo | B16: Gerados | C16: Detectados | D16: Processados | E16: Perdidos (%) | F16: CPU ocupada
A17: Polling (P = 10 ms) | B17: =IFERROR(AVERAGEIFS(Dados_SUM!$H:$H,Dados_SUM!$A:$A,"exp6b_polling_saturacao"),"sem amostras") -> 200 | C17: =IFERROR(AVERAGEIFS(Dados_SUM!$I:$I,Dados_SUM!$A:$A,"exp6b_polling_saturacao"),"sem amostras") -> 75 | D17: =IFERROR(AVERAGEIFS(Dados_SUM!$J:$J,Dados_SUM!$A:$A,"exp6b_polling_saturacao"),"sem amostras") -> 75 | E17: =IFERROR(AVERAGEIFS(Dados_SUM!$P:$P,Dados_SUM!$A:$A,"exp6b_polling_saturacao"),"sem amostras") -> 0.625 | F17: =IFERROR(AVERAGEIFS(Dados_SUM!$Q:$Q,Dados_SUM!$A:$A,"exp6b_polling_saturacao"),"sem amostras") -> 0.4387
A18: ISR + thread | B18: =IFERROR(AVERAGEIFS(Dados_SUM!$H:$H,Dados_SUM!$A:$A,"exp6b_irq_thread_saturacao"),"sem amostras") -> 200 | C18: =IFERROR(AVERAGEIFS(Dados_SUM!$I:$I,Dados_SUM!$A:$A,"exp6b_irq_thread_saturacao"),"sem amostras") -> 200 | D18: =IFERROR(AVERAGEIFS(Dados_SUM!$J:$J,Dados_SUM!$A:$A,"exp6b_irq_thread_saturacao"),"sem amostras") -> 167 | E18: =IFERROR(AVERAGEIFS(Dados_SUM!$P:$P,Dados_SUM!$A:$A,"exp6b_irq_thread_saturacao"),"sem amostras") -> 0.165 | F18: =IFERROR(AVERAGEIFS(Dados_SUM!$Q:$Q,Dados_SUM!$A:$A,"exp6b_irq_thread_saturacao"),"sem amostras") -> 0.9764
A19: ISR + work queue | B19: =IFERROR(AVERAGEIFS(Dados_SUM!$H:$H,Dados_SUM!$A:$A,"exp6b_workqueue_saturacao"),"sem amostras") -> 200 | C19: =IFERROR(AVERAGEIFS(Dados_SUM!$I:$I,Dados_SUM!$A:$A,"exp6b_workqueue_saturacao"),"sem amostras") -> 200 | D19: =IFERROR(AVERAGEIFS(Dados_SUM!$J:$J,Dados_SUM!$A:$A,"exp6b_workqueue_saturacao"),"sem amostras") -> 167 | E19: =IFERROR(AVERAGEIFS(Dados_SUM!$P:$P,Dados_SUM!$A:$A,"exp6b_workqueue_saturacao"),"sem amostras") -> 0.165 | F19: =IFERROR(AVERAGEIFS(Dados_SUM!$Q:$Q,Dados_SUM!$A:$A,"exp6b_workqueue_saturacao"),"sem amostras") -> 0.9764

Sheet Exp7
A1: Tabela 13.1 - Impacto no escalonamento (carga de 20 ms por evento)
A2: Heartbeat: thread de prioridade 0 que acorda a cada 1 ms (baseline ~1-2 ms).
A4: Modo (carga 20 ms) | B4: Maior intervalo do heartbeat (ms) | C4: CPU ocupada (kernel) | D4: CPU estimada | E4: Perdidos
A5: ISR only (anti-padrao) | B5: =IFERROR(AVERAGEIFS(Dados_SUM!$N:$N,Dados_SUM!$A:$A,"exp7_isr_only_hb"),"sem amostras") -> 21 | C5: =IFERROR(AVERAGEIFS(Dados_SUM!$Q:$Q,Dados_SUM!$A:$A,"exp7_isr_only_hb"),"sem amostras") -> 0.0012 | D5: =IFERROR(AVERAGEIFS(Dados_SUM!$R:$R,Dados_SUM!$A:$A,"exp7_isr_only_hb"),"sem amostras") -> 0.1672 | E5: =IFERROR(AVERAGEIFS(Dados_SUM!$O:$O,Dados_SUM!$A:$A,"exp7_isr_only_hb"),"sem amostras") -> 0
A6: ISR + thread | B6: =IFERROR(AVERAGEIFS(Dados_SUM!$N:$N,Dados_SUM!$A:$A,"exp7_irq_thread_hb"),"sem amostras") -> 2 | C6: =IFERROR(AVERAGEIFS(Dados_SUM!$Q:$Q,Dados_SUM!$A:$A,"exp7_irq_thread_hb"),"sem amostras") -> 0.1682 | D6: =IFERROR(AVERAGEIFS(Dados_SUM!$R:$R,Dados_SUM!$A:$A,"exp7_irq_thread_hb"),"sem amostras") -> 0.1672 | E6: =IFERROR(AVERAGEIFS(Dados_SUM!$O:$O,Dados_SUM!$A:$A,"exp7_irq_thread_hb"),"sem amostras") -> 0
A7: ISR + work queue | B7: =IFERROR(AVERAGEIFS(Dados_SUM!$N:$N,Dados_SUM!$A:$A,"exp7_workqueue_hb"),"sem amostras") -> 2 | C7: =IFERROR(AVERAGEIFS(Dados_SUM!$Q:$Q,Dados_SUM!$A:$A,"exp7_workqueue_hb"),"sem amostras") -> 0.1682 | D7: =IFERROR(AVERAGEIFS(Dados_SUM!$R:$R,Dados_SUM!$A:$A,"exp7_workqueue_hb"),"sem amostras") -> 0.1672 | E7: =IFERROR(AVERAGEIFS(Dados_SUM!$O:$O,Dados_SUM!$A:$A,"exp7_workqueue_hb"),"sem amostras") -> 0

Sheet Exp8
A1: Desafio final - processamento de 100 ms por evento
A2: sleep = k_msleep(100) (thread dorme); busy = k_busy_wait(100 ms) (consome CPU). Periodo 197 ms (~5 ev/s); rajada = periodo 47 ms (~20 ev/s) com busy. 50 eventos.
A4: Versao | B4: Cenario | C4: Gerados | D4: Processados | E4: Perdidos (%) | F4: Lat. process media (us) | G4: Lat. process max (us) | H4: Duracao do tratamento (ms) | I4: CPU ocupada | J4: CPU estimada | K4: Flash (B) | L4: RAM estatica total (B) | M4: Pilha thread evento (B)
A5: Polling | B5: sleep | C5: =IFERROR(AVERAGEIFS(Dados_SUM!$H:$H,Dados_SUM!$A:$A,"exp8_polling_sleep"),"sem amostras") -> 50 | D5: =IFERROR(AVERAGEIFS(Dados_SUM!$J:$J,Dados_SUM!$A:$A,"exp8_polling_sleep"),"sem amostras") -> 50 | E5: =IFERROR(AVERAGEIFS(Dados_SUM!$P:$P,Dados_SUM!$A:$A,"exp8_polling_sleep"),"sem amostras") -> 0 | F5: =IFERROR(AVERAGEIFS(Dados_LAT!$J:$J,Dados_LAT!$A:$A,"exp8_polling_sleep",Dados_LAT!$D:$D,"lat_process"),"sem amostras") -> 4700.458 | G5: =IFERROR(_xlfn.MAXIFS(Dados_LAT!$K:$K,Dados_LAT!$A:$A,"exp8_polling_sleep",Dados_LAT!$D:$D,"lat_process"),"sem amostras") -> 10000.008 | H5: =IFERROR(IFERROR(AVERAGEIFS(Dados_LAT!$J:$J,Dados_LAT!$A:$A,"exp8_polling_sleep",Dados_LAT!$D:$D,"lat_proc_dur"),"sem amostras")/1000,"") -> 100.99871 | I5: =IFERROR(AVERAGEIFS(Dados_SUM!$Q:$Q,Dados_SUM!$A:$A,"exp8_polling_sleep"),"sem amostras") -> 0.0001 | J5: =IFERROR(AVERAGEIFS(Dados_SUM!$R:$R,Dados_SUM!$A:$A,"exp8_polling_sleep"),"sem amostras") -> 0.4974 | K5: =INDEX(Dados_Memoria!$B:$B,MATCH("exp8_polling_sleep",Dados_Memoria!$A:$A,0)) -> 146432 | L5: =INDEX(Dados_Memoria!$F:$F,MATCH("exp8_polling_sleep",Dados_Memoria!$A:$A,0)) -> 20680 | M5: =IFERROR(TEXT(_xlfn.MAXIFS(Dados_Threads!$D:$D,Dados_Threads!$A:$A,"exp8_polling_sleep",Dados_Threads!$C:$C,"poll"),"0")&" / "&TEXT(_xlfn.MAXIFS(Dados_Threads!$E:$E,Dados_Threads!$A:$A,"exp8_polling_sleep",Dados_Threads!$C:$C,"poll"),"0"),"n/a") -> 576 / 1024
A6: Polling | B6: busy | C6: =IFERROR(AVERAGEIFS(Dados_SUM!$H:$H,Dados_SUM!$A:$A,"exp8_polling_busy"),"sem amostras") -> 50 | D6: =IFERROR(AVERAGEIFS(Dados_SUM!$J:$J,Dados_SUM!$A:$A,"exp8_polling_busy"),"sem amostras") -> 50 | E6: =IFERROR(AVERAGEIFS(Dados_SUM!$P:$P,Dados_SUM!$A:$A,"exp8_polling_busy"),"sem amostras") -> 0 | F6: =IFERROR(AVERAGEIFS(Dados_LAT!$J:$J,Dados_LAT!$A:$A,"exp8_polling_busy",Dados_LAT!$D:$D,"lat_process"),"sem amostras") -> 7999.679 | G6: =IFERROR(_xlfn.MAXIFS(Dados_LAT!$K:$K,Dados_LAT!$A:$A,"exp8_polling_busy",Dados_LAT!$D:$D,"lat_process"),"sem amostras") -> 8000.008 | H6: =IFERROR(IFERROR(AVERAGEIFS(Dados_LAT!$J:$J,Dados_LAT!$A:$A,"exp8_polling_busy",Dados_LAT!$D:$D,"lat_proc_dur"),"sem amostras")/1000,"") -> 100.00635 | I6: =IFERROR(AVERAGEIFS(Dados_SUM!$Q:$Q,Dados_SUM!$A:$A,"exp8_polling_busy"),"sem amostras") -> 0.4927 | J6: =IFERROR(AVERAGEIFS(Dados_SUM!$R:$R,Dados_SUM!$A:$A,"exp8_polling_busy"),"sem amostras") -> 0.4925 | K6: =INDEX(Dados_Memoria!$B:$B,MATCH("exp8_polling_busy",Dados_Memoria!$A:$A,0)) -> 146432 | L6: =INDEX(Dados_Memoria!$F:$F,MATCH("exp8_polling_busy",Dados_Memoria!$A:$A,0)) -> 20680 | M6: =IFERROR(TEXT(_xlfn.MAXIFS(Dados_Threads!$D:$D,Dados_Threads!$A:$A,"exp8_polling_busy",Dados_Threads!$C:$C,"poll"),"0")&" / "&TEXT(_xlfn.MAXIFS(Dados_Threads!$E:$E,Dados_Threads!$A:$A,"exp8_polling_busy",Dados_Threads!$C:$C,"poll"),"0"),"n/a") -> 576 / 1024
A7: Polling | B7: rajada | C7: =IFERROR(AVERAGEIFS(Dados_SUM!$H:$H,Dados_SUM!$A:$A,"exp8_polling_rajada"),"sem amostras") -> 50 | D7: =IFERROR(AVERAGEIFS(Dados_SUM!$J:$J,Dados_SUM!$A:$A,"exp8_polling_rajada"),"sem amostras") -> 17 | E7: =IFERROR(AVERAGEIFS(Dados_SUM!$P:$P,Dados_SUM!$A:$A,"exp8_polling_rajada"),"sem amostras") -> 0.66 | F7: =IFERROR(AVERAGEIFS(Dados_LAT!$J:$J,Dados_LAT!$A:$A,"exp8_polling_rajada",Dados_LAT!$D:$D,"lat_process"),"sem amostras") -> 4940.529 | G7: =IFERROR(_xlfn.MAXIFS(Dados_LAT!$K:$K,Dados_LAT!$A:$A,"exp8_polling_rajada",Dados_LAT!$D:$D,"lat_process"),"sem amostras") -> 10000.004 | H7: =IFERROR(IFERROR(AVERAGEIFS(Dados_LAT!$J:$J,Dados_LAT!$A:$A,"exp8_polling_rajada",Dados_LAT!$D:$D,"lat_proc_dur"),"sem amostras")/1000,"") -> 100.00617 | I7: =IFERROR(AVERAGEIFS(Dados_SUM!$Q:$Q,Dados_SUM!$A:$A,"exp8_polling_rajada"),"sem amostras") -> 0.6414 | J7: =IFERROR(AVERAGEIFS(Dados_SUM!$R:$R,Dados_SUM!$A:$A,"exp8_polling_rajada"),"sem amostras") -> 0.6413 | K7: =INDEX(Dados_Memoria!$B:$B,MATCH("exp8_polling_rajada",Dados_Memoria!$A:$A,0)) -> 146432 | L7: =INDEX(Dados_Memoria!$F:$F,MATCH("exp8_polling_rajada",Dados_Memoria!$A:$A,0)) -> 20680 | M7: =IFERROR(TEXT(_xlfn.MAXIFS(Dados_Threads!$D:$D,Dados_Threads!$A:$A,"exp8_polling_rajada",Dados_Threads!$C:$C,"poll"),"0")&" / "&TEXT(_xlfn.MAXIFS(Dados_Threads!$E:$E,Dados_Threads!$A:$A,"exp8_polling_rajada",Dados_Threads!$C:$C,"poll"),"0"),"n/a") -> 576 / 1024
A8: ISR + thread | B8: sleep | C8: =IFERROR(AVERAGEIFS(Dados_SUM!$H:$H,Dados_SUM!$A:$A,"exp8_irq_thread_sleep"),"sem amostras") -> 50 | D8: =IFERROR(AVERAGEIFS(Dados_SUM!$J:$J,Dados_SUM!$A:$A,"exp8_irq_thread_sleep"),"sem amostras") -> 50 | E8: =IFERROR(AVERAGEIFS(Dados_SUM!$P:$P,Dados_SUM!$A:$A,"exp8_irq_thread_sleep"),"sem amostras") -> 0 | F8: =IFERROR(AVERAGEIFS(Dados_LAT!$J:$J,Dados_LAT!$A:$A,"exp8_irq_thread_sleep",Dados_LAT!$D:$D,"lat_process"),"sem amostras") -> 6.708 | G8: =IFERROR(_xlfn.MAXIFS(Dados_LAT!$K:$K,Dados_LAT!$A:$A,"exp8_irq_thread_sleep",Dados_LAT!$D:$D,"lat_process"),"sem amostras") -> 6.716 | H8: =IFERROR(IFERROR(AVERAGEIFS(Dados_LAT!$J:$J,Dados_LAT!$A:$A,"exp8_irq_thread_sleep",Dados_LAT!$D:$D,"lat_proc_dur"),"sem amostras")/1000,"") -> 100.99268 | I8: =IFERROR(AVERAGEIFS(Dados_SUM!$Q:$Q,Dados_SUM!$A:$A,"exp8_irq_thread_sleep"),"sem amostras") -> 0 | J8: =IFERROR(AVERAGEIFS(Dados_SUM!$R:$R,Dados_SUM!$A:$A,"exp8_irq_thread_sleep"),"sem amostras") -> 0.4974 | K8: =INDEX(Dados_Memoria!$B:$B,MATCH("exp8_irq_thread_sleep",Dados_Memoria!$A:$A,0)) -> 146576 | L8: =INDEX(Dados_Memoria!$F:$F,MATCH("exp8_irq_thread_sleep",Dados_Memoria!$A:$A,0)) -> 20712 | M8: =IFERROR(TEXT(_xlfn.MAXIFS(Dados_Threads!$D:$D,Dados_Threads!$A:$A,"exp8_irq_thread_sleep",Dados_Threads!$C:$C,"worker"),"0")&" / "&TEXT(_xlfn.MAXIFS(Dados_Threads!$E:$E,Dados_Threads!$A:$A,"exp8_irq_thread_sleep",Dados_Threads!$C:$C,"worker"),"0"),"n/a") -> 560 / 1024
A9: ISR + thread | B9: busy | C9: =IFERROR(AVERAGEIFS(Dados_SUM!$H:$H,Dados_SUM!$A:$A,"exp8_irq_thread_busy"),"sem amostras") -> 50 | D9: =IFERROR(AVERAGEIFS(Dados_SUM!$J:$J,Dados_SUM!$A:$A,"exp8_irq_thread_busy"),"sem amostras") -> 50 | E9: =IFERROR(AVERAGEIFS(Dados_SUM!$P:$P,Dados_SUM!$A:$A,"exp8_irq_thread_busy"),"sem amostras") -> 0 | F9: =IFERROR(AVERAGEIFS(Dados_LAT!$J:$J,Dados_LAT!$A:$A,"exp8_irq_thread_busy",Dados_LAT!$D:$D,"lat_process"),"sem amostras") -> 6.708 | G9: =IFERROR(_xlfn.MAXIFS(Dados_LAT!$K:$K,Dados_LAT!$A:$A,"exp8_irq_thread_busy",Dados_LAT!$D:$D,"lat_process"),"sem amostras") -> 6.716 | H9: =IFERROR(IFERROR(AVERAGEIFS(Dados_LAT!$J:$J,Dados_LAT!$A:$A,"exp8_irq_thread_busy",Dados_LAT!$D:$D,"lat_proc_dur"),"sem amostras")/1000,"") -> 100.00634 | I9: =IFERROR(AVERAGEIFS(Dados_SUM!$Q:$Q,Dados_SUM!$A:$A,"exp8_irq_thread_busy"),"sem amostras") -> 0.4926 | J9: =IFERROR(AVERAGEIFS(Dados_SUM!$R:$R,Dados_SUM!$A:$A,"exp8_irq_thread_busy"),"sem amostras") -> 0.4925 | K9: =INDEX(Dados_Memoria!$B:$B,MATCH("exp8_irq_thread_busy",Dados_Memoria!$A:$A,0)) -> 146576 | L9: =INDEX(Dados_Memoria!$F:$F,MATCH("exp8_irq_thread_busy",Dados_Memoria!$A:$A,0)) -> 20712 | M9: =IFERROR(TEXT(_xlfn.MAXIFS(Dados_Threads!$D:$D,Dados_Threads!$A:$A,"exp8_irq_thread_busy",Dados_Threads!$C:$C,"worker"),"0")&" / "&TEXT(_xlfn.MAXIFS(Dados_Threads!$E:$E,Dados_Threads!$A:$A,"exp8_irq_thread_busy",Dados_Threads!$C:$C,"worker"),"0"),"n/a") -> 560 / 1024
A10: ISR + thread | B10: rajada | C10: =IFERROR(AVERAGEIFS(Dados_SUM!$H:$H,Dados_SUM!$A:$A,"exp8_irq_thread_rajada"),"sem amostras") -> 50 | D10: =IFERROR(AVERAGEIFS(Dados_SUM!$J:$J,Dados_SUM!$A:$A,"exp8_irq_thread_rajada"),"sem amostras") -> 26 | E10: =IFERROR(AVERAGEIFS(Dados_SUM!$P:$P,Dados_SUM!$A:$A,"exp8_irq_thread_rajada"),"sem amostras") -> 0.48 | F10: =IFERROR(AVERAGEIFS(Dados_LAT!$J:$J,Dados_LAT!$A:$A,"exp8_irq_thread_rajada",Dados_LAT!$D:$D,"lat_process"),"sem amostras") -> 26988.67 | G10: =IFERROR(_xlfn.MAXIFS(Dados_LAT!$K:$K,Dados_LAT!$A:$A,"exp8_irq_thread_rajada",Dados_LAT!$D:$D,"lat_process"),"sem amostras") -> 99189.954 | H10: =IFERROR(IFERROR(AVERAGEIFS(Dados_LAT!$J:$J,Dados_LAT!$A:$A,"exp8_irq_thread_rajada",Dados_LAT!$D:$D,"lat_proc_dur"),"sem amostras")/1000,"") -> 100.00626 | I10: =IFERROR(AVERAGEIFS(Dados_SUM!$Q:$Q,Dados_SUM!$A:$A,"exp8_irq_thread_rajada"),"sem amostras") -> 0.9808 | J10: =IFERROR(AVERAGEIFS(Dados_SUM!$R:$R,Dados_SUM!$A:$A,"exp8_irq_thread_rajada"),"sem amostras") -> 0.9808 | K10: =INDEX(Dados_Memoria!$B:$B,MATCH("exp8_irq_thread_rajada",Dados_Memoria!$A:$A,0)) -> 146576 | L10: =INDEX(Dados_Memoria!$F:$F,MATCH("exp8_irq_thread_rajada",Dados_Memoria!$A:$A,0)) -> 20712 | M10: =IFERROR(TEXT(_xlfn.MAXIFS(Dados_Threads!$D:$D,Dados_Threads!$A:$A,"exp8_irq_thread_rajada",Dados_Threads!$C:$C,"worker"),"0")&" / "&TEXT(_xlfn.MAXIFS(Dados_Threads!$E:$E,Dados_Threads!$A:$A,"exp8_irq_thread_rajada",Dados_Threads!$C:$C,"worker"),"0"),"n/a") -> 560 / 1024
A11: ISR + work queue | B11: sleep | C11: =IFERROR(AVERAGEIFS(Dados_SUM!$H:$H,Dados_SUM!$A:$A,"exp8_workqueue_sleep"),"sem amostras") -> 50 | D11: =IFERROR(AVERAGEIFS(Dados_SUM!$J:$J,Dados_SUM!$A:$A,"exp8_workqueue_sleep"),"sem amostras") -> 50 | E11: =IFERROR(AVERAGEIFS(Dados_SUM!$P:$P,Dados_SUM!$A:$A,"exp8_workqueue_sleep"),"sem amostras") -> 0 | F11: =IFERROR(AVERAGEIFS(Dados_LAT!$J:$J,Dados_LAT!$A:$A,"exp8_workqueue_sleep",Dados_LAT!$D:$D,"lat_process"),"sem amostras") -> 7.32 | G11: =IFERROR(_xlfn.MAXIFS(Dados_LAT!$K:$K,Dados_LAT!$A:$A,"exp8_workqueue_sleep",Dados_LAT!$D:$D,"lat_process"),"sem amostras") -> 7.329 | H11: =IFERROR(IFERROR(AVERAGEIFS(Dados_LAT!$J:$J,Dados_LAT!$A:$A,"exp8_workqueue_sleep",Dados_LAT!$D:$D,"lat_proc_dur"),"sem amostras")/1000,"") -> 100.99207 | I11: =IFERROR(AVERAGEIFS(Dados_SUM!$Q:$Q,Dados_SUM!$A:$A,"exp8_workqueue_sleep"),"sem amostras") -> 0 | J11: =IFERROR(AVERAGEIFS(Dados_SUM!$R:$R,Dados_SUM!$A:$A,"exp8_workqueue_sleep"),"sem amostras") -> 0.4974 | K11: =INDEX(Dados_Memoria!$B:$B,MATCH("exp8_workqueue_sleep",Dados_Memoria!$A:$A,0)) -> 146512 | L11: =INDEX(Dados_Memoria!$F:$F,MATCH("exp8_workqueue_sleep",Dados_Memoria!$A:$A,0)) -> 20752 | M11: =IFERROR(TEXT(_xlfn.MAXIFS(Dados_Threads!$D:$D,Dados_Threads!$A:$A,"exp8_workqueue_sleep",Dados_Threads!$C:$C,"sysworkq"),"0")&" / "&TEXT(_xlfn.MAXIFS(Dados_Threads!$E:$E,Dados_Threads!$A:$A,"exp8_workqueue_sleep",Dados_Threads!$C:$C,"sysworkq"),"0"),"n/a") -> 608 / 1024
A12: ISR + work queue | B12: busy | C12: =IFERROR(AVERAGEIFS(Dados_SUM!$H:$H,Dados_SUM!$A:$A,"exp8_workqueue_busy"),"sem amostras") -> 50 | D12: =IFERROR(AVERAGEIFS(Dados_SUM!$J:$J,Dados_SUM!$A:$A,"exp8_workqueue_busy"),"sem amostras") -> 50 | E12: =IFERROR(AVERAGEIFS(Dados_SUM!$P:$P,Dados_SUM!$A:$A,"exp8_workqueue_busy"),"sem amostras") -> 0 | F12: =IFERROR(AVERAGEIFS(Dados_LAT!$J:$J,Dados_LAT!$A:$A,"exp8_workqueue_busy",Dados_LAT!$D:$D,"lat_process"),"sem amostras") -> 7.316 | G12: =IFERROR(_xlfn.MAXIFS(Dados_LAT!$K:$K,Dados_LAT!$A:$A,"exp8_workqueue_busy",Dados_LAT!$D:$D,"lat_process"),"sem amostras") -> 7.329 | H12: =IFERROR(IFERROR(AVERAGEIFS(Dados_LAT!$J:$J,Dados_LAT!$A:$A,"exp8_workqueue_busy",Dados_LAT!$D:$D,"lat_proc_dur"),"sem amostras")/1000,"") -> 100.00638 | I12: =IFERROR(AVERAGEIFS(Dados_SUM!$Q:$Q,Dados_SUM!$A:$A,"exp8_workqueue_busy"),"sem amostras") -> 0.4926 | J12: =IFERROR(AVERAGEIFS(Dados_SUM!$R:$R,Dados_SUM!$A:$A,"exp8_workqueue_busy"),"sem amostras") -> 0.4925 | K12: =INDEX(Dados_Memoria!$B:$B,MATCH("exp8_workqueue_busy",Dados_Memoria!$A:$A,0)) -> 146496 | L12: =INDEX(Dados_Memoria!$F:$F,MATCH("exp8_workqueue_busy",Dados_Memoria!$A:$A,0)) -> 20752 | M12: =IFERROR(TEXT(_xlfn.MAXIFS(Dados_Threads!$D:$D,Dados_Threads!$A:$A,"exp8_workqueue_busy",Dados_Threads!$C:$C,"sysworkq"),"0")&" / "&TEXT(_xlfn.MAXIFS(Dados_Threads!$E:$E,Dados_Threads!$A:$A,"exp8_workqueue_busy",Dados_Threads!$C:$C,"sysworkq"),"0"),"n/a") -> 608 / 1024
A13: ISR + work queue | B13: rajada | C13: =IFERROR(AVERAGEIFS(Dados_SUM!$H:$H,Dados_SUM!$A:$A,"exp8_workqueue_rajada"),"sem amostras") -> 50 | D13: =IFERROR(AVERAGEIFS(Dados_SUM!$J:$J,Dados_SUM!$A:$A,"exp8_workqueue_rajada"),"sem amostras") -> 26 | E13: =IFERROR(AVERAGEIFS(Dados_SUM!$P:$P,Dados_SUM!$A:$A,"exp8_workqueue_rajada"),"sem amostras") -> 0.48 | F13: =IFERROR(AVERAGEIFS(Dados_LAT!$J:$J,Dados_LAT!$A:$A,"exp8_workqueue_rajada",Dados_LAT!$D:$D,"lat_process"),"sem amostras") -> 26994.487 | G13: =IFERROR(_xlfn.MAXIFS(Dados_LAT!$K:$K,Dados_LAT!$A:$A,"exp8_workqueue_rajada",Dados_LAT!$D:$D,"lat_process"),"sem amostras") -> 99201.07 | H13: =IFERROR(IFERROR(AVERAGEIFS(Dados_LAT!$J:$J,Dados_LAT!$A:$A,"exp8_workqueue_rajada",Dados_LAT!$D:$D,"lat_proc_dur"),"sem amostras")/1000,"") -> 100.00631 | I13: =IFERROR(AVERAGEIFS(Dados_SUM!$Q:$Q,Dados_SUM!$A:$A,"exp8_workqueue_rajada"),"sem amostras") -> 0.9808 | J13: =IFERROR(AVERAGEIFS(Dados_SUM!$R:$R,Dados_SUM!$A:$A,"exp8_workqueue_rajada"),"sem amostras") -> 0.9808 | K13: =INDEX(Dados_Memoria!$B:$B,MATCH("exp8_workqueue_rajada",Dados_Memoria!$A:$A,0)) -> 146496 | L13: =INDEX(Dados_Memoria!$F:$F,MATCH("exp8_workqueue_rajada",Dados_Memoria!$A:$A,0)) -> 20752 | M13: =IFERROR(TEXT(_xlfn.MAXIFS(Dados_Threads!$D:$D,Dados_Threads!$A:$A,"exp8_workqueue_rajada",Dados_Threads!$C:$C,"sysworkq"),"0")&" / "&TEXT(_xlfn.MAXIFS(Dados_Threads!$E:$E,Dados_Threads!$A:$A,"exp8_workqueue_rajada",Dados_Threads!$C:$C,"sysworkq"),"0"),"n/a") -> 608 / 1024
